<robot name="my_robot" xmlns:xacro="http://www.ros.org/wiki/xacro">
  <xacro:include filename="$(find my_robot)/urdf/my_robot.gazebo" />
  <link name="robot_footprint"></link>
  
  <joint name="robot_footprint_joint" type="fixed">
    <origin xyz="0 0 0" rpy="0 0 0" />
    <parent link="robot_footprint"/>
    <child link="chassis" />
  </joint>

  <link name='chassis'>
    <pose>0 0 0.1 0 0 0</pose>
  
    <inertial>
      <mass value="15.0"/>
      <origin xyz="0 0 0" rpy=" 0 0 0"/>
      <inertia
          ixx="0.1" ixy="0" ixz="0"
          iyy="0.1" iyz="0"
          izz="0.1"
      />
    </inertial>

    <collision name='collision'>
      <origin xyz="0 0 0" rpy=" 0 0 0"/>
      <geometry>
        <box size=".5 .2 .1"/>
      </geometry>
    </collision>

    <visual name='chassis_visual'>
      <origin xyz="0 0 0" rpy=" 0 0 0"/>
      <geometry>
        <box size=".5 .2 .1"/>
      </geometry>
    </visual>


    <collision name='back_caster_collision'>
      <origin xyz="-0.15 0 -0.05" rpy=" 0 0 0"/>
      <geometry>
        <sphere radius="0.0499"/>
      </geometry>
    </collision>

    <visual name='back_caster_visual'>
      <origin xyz="-0.15 0 -0.05" rpy=" 0 0 0"/>
      <geometry>
        <sphere radius="0.05"/>
      </geometry>
    </visual>

    <collision name='front_caster_collision'>
      <origin xyz="0.15 0 -0.05" rpy=" 0 0 0"/>
      <geometry>
        <sphere radius="0.0499"/>
      </geometry>
    </collision>

    <visual name='front_caster_visual'>
      <origin xyz="0.15 0 -0.05" rpy=" 0 0 0"/>
      <geometry>
        <sphere radius="0.05"/>
      </geometry>
    </visual>
  </link>

  <joint type="continuous" name="left_wheel_hinge">
    <origin xyz="0.15 0.2 0" rpy="0 0 0"/>
    <child link="left_wheel"/>
    <parent link="chassis"/>
    <axis xyz="0 1 0" rpy="0 0 0"/>
    <limit effort="10000" velocity="1000"/>
    <dynamics damping="1.0" friction="1.0"/>
    <commandTopic>cmd_vel</commandTopic>
  </joint>
  <link name="left_wheel">
    <inertial>
      <mass value="5.0"/>
      <origin xyz="0 0 0" rpy=" 0 1.57079633 1.57079633"/>
      <inertia
          ixx="0.1" ixy="0" ixz="0"
          iyy="0.1" iyz="0"
          izz="0.1"
      />
    </inertial>
    <collision name='left_wheel_collision'>
      <origin xyz="0 0 0" rpy=" 0 1.57079633 1.57079633"/>
      <geometry>
        <cylinder radius="0.1" length="0.05"/>
      </geometry>
    </collision>

    <visual name='left_wheel_visual'>
      <origin xyz="0 0 0" rpy=" 0 1.57079633 1.57079633"/>
      <geometry>
        <cylinder radius="0.1" length="0.05"/>
      </geometry>
    </visual>
  </link>
  <!-- Left Rear Dummy wheel-->
  <joint type="continuous" name="left_rear_wheel_hinge">
    <origin xyz="-0.15 0.2 0" rpy="0 0 0"/>
    <child link="left_rear_wheel"/>
    <parent link="chassis"/>
    <axis xyz="0 1 0" rpy="0 0 0"/>
    <limit effort="10000" velocity="1000"/>
    <dynamics damping="1.0" friction="1.0"/>
  </joint>
  <link name="left_rear_wheel">
    <inertial>
      <mass value="5.0"/>
      <origin xyz="0 0 0" rpy=" 0 1.57079633 1.57079633"/>
      <inertia
          ixx="0.1" ixy="0" ixz="0"
          iyy="0.1" iyz="0"
          izz="0.1"
      />
    </inertial>
    <collision name='left_rear_wheel_collision'>
      <origin xyz="0 0 0" rpy=" 0 1.57079633 1.57079633"/>
      <geometry>
        <cylinder radius="0.1" length="0.05"/>
      </geometry>
    </collision>

    <visual name='left_rear_wheel_visual'>
      <origin xyz="0 0 0" rpy=" 0 1.57079633 1.57079633"/>
      <geometry>
        <cylinder radius="0.1" length="0.05"/>
      </geometry>
    </visual>
  </link>
  
  <!-- RIGHT WHEEL -->

  <joint name="right_wheel_hinge" type="continuous">
    <parent link="chassis"/>
    <child link="right_wheel"/>
    <origin xyz="0.15 -0.2 0" rpy="0 0 0"/>
    <axis xyz="0 1 0"/>
    <limit effort="10000" velocity="1000"/>
    <dynamics damping="1.0" friction="1.0"/>
  </joint>

  <link name="right_wheel">
    <inertial>
      <mass value="5.0"/>
      <origin xyz="0 0 0" rpy="0 1.57079633 1.57079633"/>
      <inertia
          ixx="0.1" ixy="0" ixz="0"
          iyy="0.1" iyz="0"
          izz="0.1"
      />
    </inertial>
    <collision name="right_wheel_collision">
      <origin xyz="0 0 0" rpy="0 1.57079633 1.57079633"/>
      <geometry>
        <cylinder radius="0.1" length="0.05"/>
      </geometry>
    </collision>

    <visual name="right_wheel_visual">
      <origin xyz="0 0 0" rpy="0 1.57079633 1.57079633"/>
      <geometry>
        <cylinder radius="0.1" length="0.05"/>
      </geometry>
    </visual>
  </link>
  
   <!-- Rear Dummy RIGHT WHEEL -->

  <joint name="right_rear_wheel_hinge" type="continuous">
    <parent link="chassis"/>
    <child link="right_rear_wheel"/>
    <origin xyz="-0.15 -0.2 0" rpy="0 0 0"/>
    <axis xyz="0 1 0"/>
    <limit effort="10000" velocity="1000"/>
    <dynamics damping="1.0" friction="1.0"/>
  </joint>

  <link name="right_rear_wheel">
    <inertial>
      <mass value="5.0"/>
      <origin xyz="0 0 0" rpy="0 1.57079633 1.57079633"/>
      <inertia
          ixx="0.1" ixy="0" ixz="0"
          iyy="0.1" iyz="0"
          izz="0.1"
      />
    </inertial>
    <collision name="right_rear_wheel_collision">
      <origin xyz="0 0 0" rpy="0 1.57079633 1.57079633"/>
      <geometry>
        <cylinder radius="0.1" length="0.05"/>
      </geometry>
    </collision>

    <visual name="right_rear_wheel_visual">
      <origin xyz="0 0 0" rpy="0 1.57079633 1.57079633"/>
      <geometry>
        <cylinder radius="0.1" length="0.05"/>
      </geometry>
    </visual>
  </link>
  
  <!--\template for camera structure-->
  <link name="camera">
    <visual>
      <geometry>
        <box size="0.05 0.05 0.05"/>
      </geometry>
    </visual>
    <collosion>
      <geometry>
        <box size="0.05 0.05 0.05"/>
      </geometry>
    </collosion>
    <inertial>
      <mass value="0.1"/>
      <origin xyz="0 0 0" rpy=" 0 0 0"/>
      <inertia
          ixx="1e-6" ixy="0" ixz="0"
          iyy="1e-6" iyz="0"
          izz="1e-6"
      />
    </inertial>
  </link>
  
  <joint name="camera_joint" type="fixed">
    <origin xyz="0.25 0 0" rpy="0 0 0" />
    <axis xyz="0 1 0" rpy="0 0 0"/>
    <parent link="chassis"/>
    <child link="camera" />
    <imageTopicName>rgb/image_raw</imageTopicName>
  </joint>

  <!-- RGBD Camera -->
  <link name="camera_link_optical">
  </link>
 
  <joint name="camera+optical_joint" type="fixed">
    <origin xyz="0 0 0" rpy="-1.57079633 0 -1.57079633"/>
    <parent link="camera"/>
    <child link="camera_link_optical"/>
  </joint>


  

  <!--\template for LIDAR structure-->
  <link name="hokuyo">
    <visual>
      <geometry>
        <mesh filename= "package://my_robot/meshes/hokuyo.dae"/>
      </geometry>
    </visual>
    <collosion>
      <geometry>
        <box size="0.1 0.1 0.1"/>
      </geometry>
    </collosion>
    <inertial>
      <mass value="1e-5"/>
      <origin xyz="0 0 0" rpy=" 0 0 0"/>
      <inertia
          ixx="1e-6" ixy="0" ixz="0"
          iyy="1e-6" iyz="0"
          izz="1e-6"
      />
    </inertial>
  </link>

  <joint name="hokuyo_joint" type="fixed">
    <origin xyz="0.2 0 0.1" rpy="0 0 0" />
    <axis xyz="0 1 0" rpy="0 0 0"/>
    <parent link="chassis"/>
    <child link="hokuyo" />
    <topicName>/scan</topicName>
  </joint>

  <gazebo reference="chassis">
	<material>Gazebo/Orange</material>
  </gazebo>
  <gazebo reference="left_wheel">
	<material>Gazebo/Black</material>
  </gazebo>
  <gazebo reference="right_wheel">
	<material>Gazebo/Black</material>
  </gazebo>
  <gazebo reference="left_rear_wheel">
	<material>Gazebo/Black</material>
  </gazebo>
  <gazebo reference="right_rear_wheel">
	<material>Gazebo/Black</material>
  </gazebo>
  <gazebo reference="camera">
	<material>Gazebo/Blue</material>
  </gazebo>
</robot>
